<?xml version="1.0" ?>
<!-- =================================================================================== -->
<!-- |    This document was autogenerated by xacro from jetrover.xacro                 | -->
<!-- |    EDITING THIS FILE BY HAND IS NOT RECOMMENDED                                 | -->
<!-- =================================================================================== -->
<robot name="jetrover">
  <material name="black">
    <color rgba="0.1 0.1 0.1 1.0"/>
  </material>
  <material name="blue">
    <color rgba="0.0 0.0 0.8 1.0"/>
  </material>
  <material name="green">
    <color rgba="0.4 0.9 0.4 1.0"/>
  </material>
  <material name="gray">
    <color rgba="0.7 0.7 0.7 1.0"/>
  </material>
  <material name="darkgray">
    <color rgba="0.3 0.3 0.3 1.0"/>
  </material>
  <material name="red">
    <color rgba="0.8 0.0 0.0 1.0"/>
  </material>
  <material name="white">
    <color rgba="1.0 1.0 1.0 1.0"/>
  </material>
  <material name="yellow">
    <color rgba="0.8 0.8 0.0 1.0"/>
  </material>
  <link name="lidar_frame"/>
  <joint name="lidar_frame_joint" type="fixed">
    <origin rpy="0 0 3.141592653589793" xyz="0 0 0"/>
    <parent link="lidar_link"/>
    <child link="lidar_frame"/>
  </joint>
  <link name="base_footprint"/>
  <joint name="base_joint" type="fixed">
    <parent link="base_footprint"/>
    <child link="base_link"/>
    <origin rpy="0 0 0" xyz="0.0 0.0 0.11609108215767461"/>
  </joint>
  <link name="base_link">
    <inertial>
      <origin rpy="0 0 0" xyz="0 0 -0.115"/>
      <mass value="1.6"/>
      <inertia ixx="0.004333333333333334" ixy="0" ixz="0" iyy="0.013333333333333336" iyz="0" izz="0.015"/>
    </inertial>
    <visual>
      <origin rpy="0 0 0" xyz="0 0 0"/>
      <geometry>
        <mesh filename="package://jetrover_discription/meshes/mecanum/base_link.stl"/>
      </geometry>
      <material name="green"/>
    </visual>
    <collision>
      <origin rpy="0 0 0" xyz="0 0 0"/>
      <geometry>
        <mesh filename="package://jetrover_discription/meshes/mecanum/base_link_collision.stl"/>
      </geometry>
    </collision>
  </link>
  <link name="wheel_left_front_link">
    <inertial>
      <origin rpy="0 0 0" xyz="5.81479635844429E-07 -0.00227660159770525 -1.17015812418995E-06"/>
      <mass value="0.117091177510802"/>
      <inertia ixx="2.55544353224131E-05" ixy="-7.38763973128287E-11" ixz="-1.98911048317668E-10" iyy="3.98279521221712E-05" iyz="-8.29319462446527E-10" izz="2.55543299107711E-05"/>
    </inertial>
    <visual>
      <origin rpy="0 0 0" xyz="0 0 0"/>
      <geometry>
        <mesh filename="package://jetrover_discription/meshes/mecanum/wheel_left_front_link.stl"/>
      </geometry>
      <material name="black"/>
    </visual>
    <collision>
      <origin rpy="0 0 0" xyz="0 0 0"/>
      <geometry>
        <mesh filename="package://jetrover_discription/meshes/mecanum/wheel_left_front_link_collision.stl"/>
      </geometry>
    </collision>
  </link>
  <joint name="wheel_left_front_joint" type="fixed">
    <origin rpy="0 0 0" xyz="0.0975130769499663 0.11212949984639 -0.0678410821576751"/>
    <parent link="base_link"/>
    <child link="wheel_left_front_link"/>
    <axis xyz="0 0 0"/>
  </joint>
  <link name="wheel_left_back_link">
    <inertial>
      <origin rpy="0 0 0" xyz="-2.75666494506388E-07 -0.00227676419993654 -9.32882565936712E-07"/>
      <mass value="0.117085933633956"/>
      <inertia ixx="2.55538292549218E-05" ixy="4.21097022270825E-11" ixz="1.21408035187706E-10" iyy="3.98269234728938E-05" iyz="-9.0594889488305E-10" izz="2.55538443721092E-05"/>
    </inertial>
    <visual>
      <origin rpy="0 0 0" xyz="0 0 0"/>
      <geometry>
        <mesh filename="package://jetrover_discription/meshes/mecanum/wheel_left_back_link.stl"/>
      </geometry>
      <material name="black"/>
    </visual>
    <collision>
      <origin rpy="0 0 0" xyz="0 0 0"/>
      <geometry>
        <mesh filename="package://jetrover_discription/meshes/mecanum/wheel_left_back_link_collision.stl"/>
      </geometry>
    </collision>
  </link>
  <joint name="wheel_left_back_joint" type="fixed">
    <origin rpy="0 0 0" xyz="-0.0975130776687404 0.112129499199832 -0.0678410821576746"/>
    <parent link="base_link"/>
    <child link="wheel_left_back_link"/>
    <axis xyz="0 0 0"/>
  </joint>
  <link name="wheel_right_front_link">
    <inertial>
      <origin rpy="0 0 0" xyz="5.44451075196184E-08 0.00227682317165415 -9.47357195397124E-07"/>
      <mass value="0.117085770467945"/>
      <inertia ixx="2.55536357316359E-05" ixy="5.69813318109323E-11" ixz="2.38465881815206E-11" iyy="3.98269286073969E-05" iyz="6.83419343386592E-10" izz="2.5554047832082E-05"/>
    </inertial>
    <visual>
      <origin rpy="0 0 0" xyz="0 0 0"/>
      <geometry>
        <mesh filename="package://jetrover_discription/meshes/mecanum/wheel_right_front_link.stl"/>
      </geometry>
      <material name="black"/>
    </visual>
    <collision>
      <origin rpy="0 0 0" xyz="0 0 0"/>
      <geometry>
        <mesh filename="package://jetrover_discription/meshes/mecanum/wheel_right_front_link_collision.stl"/>
      </geometry>
    </collision>
  </link>
  <joint name="wheel_right_front_joint" type="fixed">
    <origin rpy="0 0 0" xyz="0.0975130776687398 -0.112129499199832 -0.0678410821576747"/>
    <parent link="base_link"/>
    <child link="wheel_right_front_link"/>
    <axis xyz="0 0 0"/>
  </joint>
  <link name="wheel_right_back_link">
    <inertial>
      <origin rpy="0 0 0" xyz="-3.46320503386011E-08 0.00227648207696338 -1.0053051795033E-06"/>
      <mass value="0.117089422641222"/>
      <inertia ixx="2.55538960057458E-05" ixy="3.31620843526057E-11" ixz="4.70244411980948E-11" iyy="3.98267817478014E-05" iyz="8.12919631247531E-10" izz="2.5553677758516E-05"/>
    </inertial>
    <visual>
      <origin rpy="0 0 0" xyz="0 0 0"/>
      <geometry>
        <mesh filename="package://jetrover_discription/meshes/mecanum/wheel_right_back_link.stl"/>
      </geometry>
      <material name="black"/>
    </visual>
    <collision>
      <origin rpy="0 0 0" xyz="0 0 0"/>
      <geometry>
        <mesh filename="package://jetrover_discription/meshes/mecanum/wheel_right_back_link_collision.stl"/>
      </geometry>
    </collision>
  </link>
  <joint name="wheel_right_back_joint" type="fixed">
    <origin rpy="0 0 0" xyz="-0.097513076949967 -0.11212949984639 -0.0678410821576744"/>
    <parent link="base_link"/>
    <child link="wheel_right_back_link"/>
    <axis xyz="0 0 0"/>
  </joint>
  <link name="lidar_link">
    <inertial>
      <origin rpy="0 0 0" xyz="-0.000511459223461241 -0.00026215532436116 -0.0101267502723355"/>
      <mass value="0.165604343849592"/>
      <inertia ixx="5.88498679907636E-05" ixy="4.6459735242599E-07" ixz="-1.56610114830903E-07" iyy="5.96988334453293E-05" iyz="-8.03105723289238E-08" izz="0.000108238967260097"/>
    </inertial>
    <visual>
      <origin rpy="0 0 0" xyz="0 0 0"/>
      <geometry>
        <mesh filename="package://jetrover_discription/meshes/common/lidar_link.stl"/>
      </geometry>
      <material name="black"/>
    </visual>
    <!--<collision>-->
    <!--<origin-->
    <!--xyz="0 0 0"-->
    <!--rpy="0 0 0" />-->
    <!--<geometry>-->
    <!--<mesh-->
    <!--filename="package://jetrover_discription/meshes/common/lidar_link.stl" />-->
    <!--</geometry>-->
    <!--</collision>-->
  </link>
  <joint name="lidar_joint" type="fixed">
    <origin rpy="0 0 0" xyz="0.0900034859353204 0 0.0405195774179554"/>
    <parent link="base_link"/>
    <child link="lidar_link"/>
    <axis xyz="0 0 0"/>
  </joint>
  <link name="imu_link">
    <inertial>
      <origin rpy="0 0 0" xyz="-0.015992956442504 -0.0186967363878791 0.00080000000000012"/>
      <mass value="0.00900725791925823"/>
      <inertia ixx="6.0621502887195E-06" ixy="8.2009503850481E-10" ixz="1.00078505419116E-16" iyy="2.95825733414683E-06" iyz="4.74614002484179E-17" izz="9.01656451992273E-06"/>
    </inertial>
    <visual>
      <origin rpy="0 0 0" xyz="0 0 0"/>
      <geometry>
        <mesh filename="package://jetrover_discription/meshes/common/imu_link.stl"/>
      </geometry>
      <material name="black"/>
    </visual>
    <collision>
      <origin rpy="0 0 0" xyz="0 0 0"/>
      <geometry>
        <mesh filename="package://jetrover_discription/meshes/common/imu_link.stl"/>
      </geometry>
    </collision>
  </link>
  <joint name="imu_joint" type="fixed">
    <origin rpy="3.141592653589793 0 -1.5707963267948966" xyz="0.0048416 0.011168 -0.0057398"/>
    <parent link="base_link"/>
    <child link="imu_link"/>
    <axis xyz="0 0 0"/>
  </joint>
  <link name="camera_connect_link">
    <inertial>
      <origin rpy="0 0 0" xyz="-0.00050566 0.010186 0.0012735"/>
      <mass value="0.0029007"/>
      <inertia ixx="4.5276E-07" ixy="-3.2151E-10" ixz="-8.627E-12" iyy="5.4068E-07" iyz="-1.2081E-08" izz="9.9085E-07"/>
    </inertial>
    <visual>
      <origin rpy="0 0 0" xyz="0 0 0"/>
      <geometry>
        <mesh filename="package://jetrover_discription/meshes/arm/camera_connect_link.STL"/>
      </geometry>
      <material name="black"/>
    </visual>
    <collision>
      <origin rpy="0 0 0" xyz="0 0 0"/>
      <geometry>
        <mesh filename="package://jetrover_discription/meshes/arm/camera_connect_link.STL"/>
      </geometry>
    </collision>
  </link>
  <joint name="camera_connect_joint" type="fixed">
    <origin rpy="0 0 -1.57079632679489" xyz="-0.0507060266977644 0 0.0505384841187764"/>
    <parent link="link4"/>
    <child link="camera_connect_link"/>
    <axis xyz="0 0 0"/>
  </joint>
  <link name="depth_cam_link">
    <inertial>
      <origin rpy="0 0 0" xyz="0.00232981322860787 0.000387137406184821 -2.84059740606052E-05"/>
      <mass value="0.015428"/>
      <inertia ixx="1.3945E-06" ixy="-1.5684E-08" ixz="-2.3104E-07" iyy="1.2848E-05" iyz="1.3156E-09" izz="1.361E-05"/>
    </inertial>
    <visual>
      <origin rpy="0 0 0" xyz="0 0 0"/>
      <geometry>
        <mesh filename="package://jetrover_discription/meshes/arm/depth_cam_link.STL"/>
      </geometry>
      <material name="">
        <color rgba="0.753 0.753 0.753 1"/>
      </material>
    </visual>
    <collision>
      <origin rpy="0 0 0" xyz="0 0 0"/>
      <geometry>
        <mesh filename="package://jetrover_discription/meshes/arm/depth_cam_link_collision.stl"/>
      </geometry>
    </collision>
  </link>
  <joint name="depth_cam_joint" type="fixed">
    <origin rpy="3.141592653589793 -1.5707963267948966 -1.5707963267948966" xyz="0 0.0 0.014475"/>
    <parent link="camera_connect_link"/>
    <child link="depth_cam_link"/>
    <axis xyz="0 0 0"/>
  </joint>
  <link name="depth_cam_frame"/>
  <joint name="depth_cam_joint_sim" type="fixed">
    <origin rpy="-1.5707963267948966 0 -1.5707963267948966" xyz="0 0 0"/>
    <parent link="depth_cam_link"/>
    <child link="depth_cam_frame"/>
  </joint>
  <link name="back_shell_black_link">
    <inertial>
      <origin rpy="0 0 0" xyz="-0.128102112274456 1.72211525746893E-05 0.0928043689724126"/>
      <mass value="0.275421428635453"/>
      <inertia ixx="0.000628323854310952" ixy="8.12787450972555E-08" ixz="-5.57405274002875E-05" iyy="0.000218971510417661" iyz="1.78950516503852E-07" izz="0.000550804966985301"/>
    </inertial>
    <visual>
      <origin rpy="0 0 0" xyz="0 0 0"/>
      <geometry>
        <mesh filename="package://jetrover_discription/meshes/common/back_shell_black_link.stl"/>
      </geometry>
      <material name="black"/>
    </visual>
    <collision>
      <origin rpy="0 0 0" xyz="0 0 0"/>
      <geometry>
        <mesh filename="package://jetrover_discription/meshes/common/back_shell_black_link_collision.stl"/>
      </geometry>
    </collision>
  </link>
  <joint name="back_shell_black_joint" type="fixed">
    <origin rpy="0 0 0" xyz="-0.00800423021156377 0.000186898416208928 0"/>
    <parent link="base_link"/>
    <child link="back_shell_black_link"/>
    <axis xyz="0 0 0"/>
  </joint>
  <link name="back_shell_green_link">
    <inertial>
      <origin rpy="0 0 0" xyz="0.0307901265873789 -0.000113109105123149 0.020162111142601"/>
      <mass value="0.186020370555428"/>
      <inertia ixx="0.000313865003161158" ixy="2.65289062493475E-07" ixz="1.61671612029607E-05" iyy="0.00101596189150751" iyz="-6.02076716251901E-08" izz="0.00128044252632698"/>
    </inertial>
    <visual>
      <origin rpy="0 0 0" xyz="0 0 0"/>
      <geometry>
        <mesh filename="package://jetrover_discription/meshes/common/back_shell_green_link.stl"/>
      </geometry>
      <material name="green"/>
    </visual>
    <collision>
      <origin rpy="0 0 0" xyz="0 0 0"/>
      <geometry>
        <mesh filename="package://jetrover_discription/meshes/common/back_shell_green_link_collision.stl"/>
      </geometry>
    </collision>
  </link>
  <joint name="back_shell_green_joint" type="fixed">
    <origin rpy="0 0 0" xyz="-0.0080042 0.0001869 0"/>
    <parent link="base_link"/>
    <child link="back_shell_green_link"/>
    <axis xyz="0 0 0"/>
  </joint>
  <joint name="joint1" type="revolute">
    <origin rpy="0 0 0" xyz="0.0251328065010765 0 0.0774026880954513"/>
    <parent link="base_link"/>
    <child link="link1"/>
    <axis xyz="0 0 -1"/>
    <limit effort="1000" lower="-2.09" upper="2.09" velocity="10"/>
  </joint>
  <link name="link1">
    <inertial>
      <origin rpy="0 0 0" xyz="9.55287669839149E-05 0.000953445773182543 0.0181622223429797"/>
      <mass value="0.018996290781889"/>
      <inertia ixx="3.52401713486466E-06" ixy="-9.57766622211234E-11" ixz="1.77834467690429E-11" iyy="2.92480468671507E-06" iyz="2.27263787135776E-08" izz="2.43231516201483E-06"/>
    </inertial>
    <visual>
      <origin rpy="0 0 0" xyz="0 0 0"/>
      <geometry>
        <mesh filename="package://jetrover_discription/meshes/arm/link1.STL"/>
      </geometry>
      <material name="green"/>
    </visual>
    <collision>
      <origin rpy="0 0 0" xyz="0 0 0"/>
      <geometry>
        <mesh filename="package://jetrover_discription/meshes/arm/link1.STL"/>
      </geometry>
    </collision>
  </link>
  <link name="servo_link1">
    <inertial>
      <origin rpy="0 0 0" xyz="6.74971199241745E-05 -0.00653404855626152 0.0238958340366914"/>
      <mass value="0.0116330609777772"/>
      <inertia ixx="1.75977694435981E-06" ixy="-9.73060826949638E-11" ixz="2.47639220332551E-12" iyy="2.04910641988494E-06" iyz="-1.98639869902586E-08" izz="5.57260556249774E-07"/>
    </inertial>
    <visual>
      <origin rpy="0 0 0" xyz="0 0 0"/>
      <geometry>
        <mesh filename="package://jetrover_discription/meshes/arm/servo_link1.STL"/>
      </geometry>
      <material name="black"/>
    </visual>
    <collision>
      <origin rpy="0 0 0" xyz="0 0 0"/>
      <geometry>
        <mesh filename="package://jetrover_discription/meshes/arm/servo_link1_collision.stl"/>
      </geometry>
    </collision>
  </link>
  <joint name="servo_joint1" type="fixed">
    <origin rpy="0 0 0" xyz="0 0 0"/>
    <parent link="link1"/>
    <child link="servo_link1"/>
    <axis xyz="0 0 0"/>
  </joint>
  <link name="link2">
    <inertial>
      <origin rpy="0 0 0" xyz="0.000156299570425157 -0.000455113699913916 0.0717727028511975"/>
      <mass value="0.0329250074531705"/>
      <inertia ixx="3.91620966174037E-05" ixy="-5.45461883923424E-11" ixz="-1.84994427464167E-07" iyy="3.08453562297899E-05" iyz="3.5881427402197E-09" izz="1.15081900975983E-05"/>
    </inertial>
    <visual>
      <origin rpy="0 0 0" xyz="0 0 0"/>
      <geometry>
        <mesh filename="package://jetrover_discription/meshes/arm/link2.STL"/>
      </geometry>
      <material name="green"/>
    </visual>
    <collision>
      <origin rpy="0 0 0" xyz="0 0 0"/>
      <geometry>
        <mesh filename="package://jetrover_discription/meshes/arm/link2_collision.stl"/>
      </geometry>
    </collision>
  </link>
  <joint name="joint2" type="revolute">
    <origin rpy="0 0 0" xyz="0 0 0.0338648012164686"/>
    <parent link="servo_link1"/>
    <child link="link2"/>
    <axis xyz="0 1 0"/>
    <limit effort="1000" lower="-2.09" upper="2.09" velocity="10"/>
  </joint>
  <link name="link3">
    <inertial>
      <origin rpy="0 0 0" xyz="0.000128456440925698 -0.000761424622733717 0.071772743785429"/>
      <mass value="0.0329250074463074"/>
      <inertia ixx="3.91621699579612E-05" ixy="-5.40097530558062E-11" ixz="-1.73786652512013E-07" iyy="3.08451969920239E-05" iyz="3.63874236522223E-09" izz="1.15078234912494E-05"/>
    </inertial>
    <visual>
      <origin rpy="0 0 0" xyz="0 0 0"/>
      <geometry>
        <mesh filename="package://jetrover_discription/meshes/arm/link3.STL"/>
      </geometry>
      <material name="green"/>
    </visual>
    <collision>
      <origin rpy="0 0 0" xyz="0 0 0"/>
      <geometry>
        <mesh filename="package://jetrover_discription/meshes/arm/link3_collision.stl"/>
      </geometry>
    </collision>
  </link>
  <joint name="joint3" type="revolute">
    <origin rpy="0 0 0" xyz="0 0 0.129416446394797"/>
    <parent link="link2"/>
    <child link="link3"/>
    <axis xyz="0 1 0"/>
    <limit effort="1000" lower="-2.09" upper="2.09" velocity="10"/>
  </joint>
  <link name="link4">
    <inertial>
      <origin rpy="0 0 0" xyz="-0.000261855576526311 0.000239368359066633 0.0220971301535388"/>
      <mass value="0.00959141779390409"/>
      <inertia ixx="7.94977139591732E-06" ixy="-8.29446018776969E-10" ixz="5.6880898756802E-08" iyy="4.29063067361656E-06" iyz="-1.84622131688891E-10" izz="5.33833388813501E-06"/>
    </inertial>
    <visual>
      <origin rpy="0 0 0" xyz="0 0 0"/>
      <geometry>
        <mesh filename="package://jetrover_discription/meshes/arm/link4.STL"/>
      </geometry>
      <material name="green"/>
    </visual>
    <collision>
      <origin rpy="0 0 0" xyz="0 0 0"/>
      <geometry>
        <mesh filename="package://jetrover_discription/meshes/arm/link4_collision.stl"/>
      </geometry>
    </collision>
  </link>
  <joint name="joint4" type="revolute">
    <origin rpy="0 0 0" xyz="0 0 0.129444631186569"/>
    <parent link="link3"/>
    <child link="link4"/>
    <axis xyz="0 1 0"/>
    <limit effort="1000" lower="-2.09" upper="2.09" velocity="10"/>
  </joint>
  <link name="servo_link2">
    <inertial>
      <origin rpy="0 0 0" xyz="0.00829457691057159 0.000114732113040695 -0.0125525321145837"/>
      <mass value="0.00701021225113507"/>
      <inertia ixx="6.10646998888003E-07" ixy="1.66839713815154E-09" ixz="-2.07626862362467E-08" iyy="9.477990166652E-07" iyz="5.12927100881908E-09" izz="1.44691449724265E-06"/>
    </inertial>
    <visual>
      <origin rpy="0 0 0" xyz="0 0 0"/>
      <geometry>
        <mesh filename="package://jetrover_discription/meshes/arm/servo_link2.STL"/>
      </geometry>
      <material name="black"/>
    </visual>
    <collision>
      <origin rpy="0 0 0" xyz="0 0 0"/>
      <geometry>
        <mesh filename="package://jetrover_discription/meshes/arm/servo_link2_collision.stl"/>
      </geometry>
    </collision>
  </link>
  <joint name="servo_joint2" type="fixed">
    <origin rpy="0 0 0" xyz="0 0 0.0544833339503674"/>
    <parent link="link4"/>
    <child link="servo_link2"/>
    <axis xyz="0 0 0"/>
  </joint>
  <link name="link5">
    <inertial>
      <origin rpy="0 0 0" xyz="-5.40141895711381E-05 -8.30141354428709E-06 0.00351551092860852"/>
      <mass value="0.00101775298619909"/>
      <inertia ixx="2.35834256739382E-08" ixy="-1.92177809145012E-12" ixz="-3.88572739181837E-12" iyy="2.35740360938003E-08" iyz="-1.1228386368903E-13" izz="4.40224050991292E-08"/>
    </inertial>
    <visual>
      <origin rpy="0 0 0" xyz="0 0 0"/>
      <geometry>
        <mesh filename="package://jetrover_discription/meshes/arm/link5.STL"/>
      </geometry>
      <material name="black"/>
    </visual>
    <collision>
      <origin rpy="0 0 0" xyz="0 0 0"/>
      <geometry>
        <mesh filename="package://jetrover_discription/meshes/arm/link5.STL"/>
      </geometry>
    </collision>
  </link>
  <joint name="joint5" type="revolute">
    <origin rpy="0 0 0" xyz="0 0 0"/>
    <parent link="servo_link2"/>
    <child link="link5"/>
    <axis xyz="0 0 -1"/>
    <limit effort="1000" lower="-2.09" upper="2.09" velocity="10"/>
  </joint>
  <link name="gripper_link">
    <inertial>
      <origin rpy="0 0 0" xyz="0.0145481835889059 -0.00315257290321308 0.0253492053712461"/>
      <mass value="0.0174988490314194"/>
      <inertia ixx="4.12615692688456E-06" ixy="-2.75102939068049E-08" ixz="-7.61180742281118E-09" iyy="1.57023365316943E-06" iyz="2.2563082379695E-08" izz="3.2612101868791E-06"/>
    </inertial>
    <visual>
      <origin rpy="0 0 0" xyz="0 0 0"/>
      <geometry>
        <mesh filename="package://jetrover_discription/meshes/arm/gripper_link.STL"/>
      </geometry>
      <material name="black"/>
    </visual>
    <collision>
      <origin rpy="0 0 0" xyz="0 0 0"/>
      <geometry>
        <mesh filename="package://jetrover_discription/meshes/arm/gripper_link_collision.stl"/>
      </geometry>
    </collision>
  </link>
  <joint name="gripper_joint" type="fixed">
    <origin rpy="0 0 0" xyz="0 0 0.0054388"/>
    <parent link="link5"/>
    <child link="gripper_link"/>
    <axis xyz="0 0 0"/>
  </joint>
  <!-- end effector link -->
  <link name="end_effector_link"/>
  <joint name="end_effector_joint" type="fixed">
    <!-- <origin rpy="0 0 0" xyz="0 0 0.08"/> -->
    <origin rpy="0 0 0" xyz="0 0 0.113"/> 

    <parent link="link5"/>
    <child link="end_effector_link"/>
  </joint>
  <link name="r_link">
    <inertial>
      <origin rpy="0 0 0" xyz="0.00154652142582958 0.000534112070478834 0.00624030428121536"/>
      <mass value="0.00206265647704866"/>
      <inertia ixx="3.97215843669342E-07" ixy="-2.75699120579387E-10" ixz="-2.19901048536124E-09" iyy="3.22472627342115E-07" iyz="1.07303783544668E-08" izz="7.78708186672131E-08"/>
    </inertial>
    <visual>
      <origin rpy="0 0 0" xyz="0 0 0"/>
      <geometry>
        <mesh filename="package://jetrover_discription/meshes/gripper/r_link.STL"/>
      </geometry>
      <material name="black"/>
    </visual>
    <collision>
      <origin rpy="0 0 0" xyz="0 0 0"/>
      <geometry>
        <mesh filename="package://jetrover_discription/meshes/gripper/r_link.STL"/>
      </geometry>
    </collision>
  </link>
  <joint name="r_joint" type="revolute">
    <origin rpy="0 0 0" xyz="-0.0073166 -0.013992 0.027059"/>
    <parent link="gripper_link"/>
    <child link="r_link"/>
    <axis xyz="0.99996 -0.004699 -0.0070434"/>
    <limit effort="1000" lower="-1.57" upper="1.57" velocity="10"/>
  </joint>
  <link name="l_link">
    <inertial>
      <origin rpy="0 0 0" xyz="0.0015384031888858 -0.000403232726847674 0.00579759783012201"/>
      <mass value="0.00218924933187322"/>
      <inertia ixx="4.0534152698165E-07" ixy="3.60077827494503E-10" ixz="-1.99675888093364E-09" iyy="3.31222174181852E-07" iyz="-8.79337758250917E-09" izz="7.74319582642917E-08"/>
    </inertial>
    <visual>
      <origin rpy="0 0 0" xyz="0 0 0"/>
      <geometry>
        <mesh filename="package://jetrover_discription/meshes/gripper/l_link.STL"/>
      </geometry>
      <material name="black"/>
    </visual>
    <collision>
      <origin rpy="0 0 0" xyz="0 0 0"/>
      <geometry>
        <mesh filename="package://jetrover_discription/meshes/gripper/l_link.STL"/>
      </geometry>
    </collision>
  </link>
  <joint name="l_joint" type="revolute">
    <origin rpy="0 0 0" xyz="-0.0073352 0.013977 0.027057"/>
    <parent link="gripper_link"/>
    <child link="l_link"/>
    <axis xyz="0.99997 0.0055811 -0.0058397"/>
    <limit effort="1000" lower="-1.57" upper="1.57" velocity="10"/>
    <mimic joint="r_joint" multiplier="-1" offset="0"/>
  </joint>
  <link name="l_in_link">
    <inertial>
      <origin rpy="0 0 0" xyz="0.00610191812065245 2.91459132896708E-05 0.0144573768632076"/>
      <mass value="0.000776872870694597"/>
      <inertia ixx="9.87455572181138E-08" ixy="5.06340928475727E-12" ixz="-6.79685646256186E-10" iyy="9.76635148452203E-08" iyz="-6.12115908323794E-12" izz="2.25695364751658E-09"/>
    </inertial>
    <visual>
      <origin rpy="0 0 0" xyz="0 0 0"/>
      <geometry>
        <mesh filename="package://jetrover_discription/meshes/gripper/l_in_link.STL"/>
      </geometry>
      <material name="black"/>
    </visual>
    <collision>
      <origin rpy="0 0 0" xyz="0 0 0"/>
      <geometry>
        <mesh filename="package://jetrover_discription/meshes/gripper/l_in_link.STL"/>
      </geometry>
    </collision>
  </link>
  <joint name="l_in_joint" type="revolute">
    <origin rpy="0 0 0" xyz="-0.0071623 0.0049403 0.046019"/>
    <parent link="gripper_link"/>
    <child link="l_in_link"/>
    <axis xyz="0.99996 0.0046983 -0.0070439"/>
    <limit effort="1000" lower="-1.57" upper="1.57" velocity="10"/>
    <mimic joint="r_joint" multiplier="-1" offset="0"/>
  </joint>
  <link name="l_out_link">
    <inertial>
      <origin rpy="0 0 0" xyz="0.00602407836518577 0.0014461936314294 0.00961214041434189"/>
      <mass value="0.00384735908281124"/>
      <inertia ixx="8.77337978935691E-07" ixy="1.36760329013846E-09" ixz="-6.9462127438421E-09" iyy="8.19648792008027E-07" iyz="1.56177294727923E-07" izz="7.0687486597803E-08"/>
    </inertial>
    <visual>
      <origin rpy="0 0 0" xyz="0 0 0"/>
      <geometry>
        <mesh filename="package://jetrover_discription/meshes/gripper/l_out_link.STL"/>
      </geometry>
      <material name="black"/>
    </visual>
    <collision>
      <origin rpy="0 0 0" xyz="0 0 0"/>
      <geometry>
        <mesh filename="package://jetrover_discription/meshes/gripper/l_out_link.STL"/>
      </geometry>
    </collision>
  </link>
  <joint name="l_out_joint" type="revolute">
    <origin rpy="0 0 0" xyz="0.00020427 0 0.028999"/>
    <parent link="l_in_link"/>
    <child link="l_out_link"/>
    <axis xyz="0.99996 0.0046983 -0.0070439"/>
    <limit effort="1000" lower="-1.57" upper="1.57" velocity="10"/>
    <mimic joint="r_joint" multiplier="1" offset="0"/>
  </joint>
  <link name="r_in_link">
    <inertial>
      <origin rpy="0 0 0" xyz="0.00610191812065006 -2.81924690068705E-05 0.0144573787538957"/>
      <mass value="0.000776872870694522"/>
      <inertia ixx="9.87465668171204E-08" ixy="-5.11173808106636E-12" ixz="-6.79692406191707E-10" iyy="9.7664293636849E-08" iyz="-5.14018800149497E-13" izz="2.25718458778487E-09"/>
    </inertial>
    <visual>
      <origin rpy="0 0 0" xyz="0 0 0"/>
      <geometry>
        <mesh filename="package://jetrover_discription/meshes/gripper/r_in_link.STL"/>
      </geometry>
      <material name="black"/>
    </visual>
    <collision>
      <origin rpy="0 0 0" xyz="0 0 0"/>
      <geometry>
        <mesh filename="package://jetrover_discription/meshes/gripper/r_in_link.STL"/>
      </geometry>
    </collision>
  </link>
  <joint name="r_in_joint" type="revolute">
    <origin rpy="0 0 0" xyz="-0.0071623 -0.004943 0.046019"/>
    <parent link="gripper_link"/>
    <child link="r_in_link"/>
    <axis xyz="-0.99996 0.0046987 0.0070436"/>
    <limit effort="1000" lower="-1.57" upper="1.57" velocity="10"/>
    <mimic joint="r_joint" multiplier="-1" offset="0"/>
  </joint>
  <link name="r_out_link">
    <inertial>
      <origin rpy="0 0 0" xyz="0.0060622 -0.0014474 0.0096107"/>
      <mass value="0.0038474"/>
      <inertia ixx="8.7734E-07" ixy="-1.2815E-09" ixz="-6.7006E-09" iyy="8.1957E-07" iyz="-1.5635E-07" izz="7.0761E-08"/>
    </inertial>
    <visual>
      <origin rpy="0 0 0" xyz="0 0 0"/>
      <geometry>
        <mesh filename="package://jetrover_discription/meshes/gripper/r_out_link.STL"/>
      </geometry>
      <material name="black"/>
    </visual>
    <collision>
      <origin rpy="0 0 0" xyz="0 0 0"/>
      <geometry>
        <mesh filename="package://jetrover_discription/meshes/gripper/r_out_link.STL"/>
      </geometry>
    </collision>
  </link>
  <joint name="r_out_joint" type="revolute">
    <origin rpy="0 0 0" xyz="0.00020427 0 0.028999"/>
    <parent link="r_in_link"/>
    <child link="r_out_link"/>
    <axis xyz="-0.99996 0.0046987 0.0070436"/>
    <limit effort="1000" lower="-1.57" upper="1.57" velocity="10"/>
    <mimic joint="r_joint" multiplier="1" offset="0"/>
  </joint>
</robot>
